Workbook

Sheet Read Me
A1: AWS 1P Public Sector Symposiums - Pricing Model
A2: This workbook mirrors pricing.config.js in the aws-1p-symposiums-proposal site. Same roles, rates, hour formulas, modifiers, and tier presets.
A4: HOW TO USE
A5: Blue cells are inputs you can change. Black cells are formulas; do not overwrite them.
A6: Assumptions sheet: rates, base hours by writing depth, modifiers, and tier presets. Edit blue values and the Calculator updates.
A7: Calculator sheet: London, Ottawa, and Canberra pull their inputs from the tier presets (Lean / Signature / Premium). The Custom column is free-form.
A9: FEEDING CHANGES BACK TO THE SITE
A10: Every input on the Assumptions sheet lists its config key. To update the live site, change the matching value in pricing.config.js (or send this file back to Elliot and the config gets updated from it).
A12: THE MATH, PER DECK
A13: 1. Writing depth sets absolute base hours per level.
A14: 2. Modifiers add hours: slides above 20 add design time, each speaker adds speaker management, each edit round adds design and writing, each dry run adds PM and writing.
A15: 3. Cost = sum of role hours x rates, plus flat on-site day rate x days.
... A18: ALL NUMBERS ARE PLACEHOLDERS PENDING CONFIRMATION. Estimate, not a quote.

Sheet Assumptions
A1: Pricing Model Assumptions
A2: Blue = editable input. Black = calculated. Config key shows where each value lives in pricing.config.js. On-site days of 0 = no on-site support.
A4: Role rates
A5: Role | B5: Rate | C5: Unit | H5: Config key
A6: Content Strategy / Writing | B6: 185 | C6: $/hr | H6: roles[writing].rate
A7: Speaker Management | B7: 185 | C7: $/hr | H7: roles[speakerMgmt].rate
A8: Design | B8: 175 | C8: $/hr | H8: roles[design].rate
A9: Design Direction | B9: 200 | C9: $/hr | H9: roles[designDir].rate
A10: Project Management | B10: 175 | C10: $/hr | H10: roles[pm].rate
A11: Quality Control | B11: 100 | C11: $/hr | H11: roles[qc].rate
A12: On-Site Support (flat) | B12: 3500 | C12: $/day | H12: onSite.dayRate
A13: Round prices UP to nearest | B13: 100 | C13: $ | H13: roundUpTo
A16: Base hours per deck by writing depth
A17: Absolute base hours per deck for each level, matching depthLevels[].hours in the config.
A18: Role | B18: L1: Deck mods only | C18: L2: Scripting from framework | D18: L3: Full narrative + scripting | H18: Config key
A19: Content Strategy / Writing | B19: 4 | C19: 20 | D19: 48 | H19: depthLevels[].hours.writing
A20: Speaker Management | B20: 0 | C20: 8 | D20: 22 | H20: depthLevels[].hours.speakerMgmt
A21: Design | B21: 20 | C21: 20 | D21: 20 | H21: depthLevels[].hours.design
A22: Design Direction | B22: 3 | C22: 3 | D22: 8 | H22: depthLevels[].hours.designDir
A23: Project Management | B23: 6 | C23: 6 | D23: 6 | H23: depthLevels[].hours.pm
A24: Quality Control | B24: 5 | C24: 5 | D24: 5 | H24: depthLevels[].hours.qc
A27: Modifiers (added on top of base hours)
A28: Modifier | B28: Value | H28: Config key
A29: Slides included in base | B29: 20 | H29: modifiers.slidesIncluded
A30: Design hours per extra slide | B30: 0.6 | H30: modifiers.designHoursPerExtraSlide
A31: Speaker Mgmt hours per speaker | B31: 3 | H31: modifiers.speakerMgmtHoursPerSpeaker
A32: Design hours per edit round | B32: 4 | H32: modifiers.perEditRound.design
A33: Writing hours per edit round | B33: 2 | H33: modifiers.perEditRound.writing
A34: PM hours per dry run | B34: 4 | H34: modifiers.perDryRun.pm
A35: Writing hours per dry run | B35: 3 | H35: modifiers.perDryRun.writing
A38: Tier presets
A39: On-site days of 0 means on-site support is off. Depth: 1 = Deck mods only, 2 = Scripting from framework, 3 = Full narrative + scripting.
A40: Tier | B40: Slides per deck | C40: Depth (1-3) | D40: Speakers | E40: Edit rounds | F40: Dry runs | G40: On-site days | H40: Config key
A41: Lean | B41: 20 | C41: 1 | D41: 3 | E41: 2 | F41: 1 | G41: 0 | H41: tiers[lean].preset
A42: Signature | B42: 35 | C42: 2 | D42: 4 | E42: 3 | F42: 2 | G42: 1 | H42: tiers[signature].preset
A43: Premium | B43: 50 | C43: 3 | D43: 5 | E43: 4 | F43: 3 | G43: 2 | H43: tiers[premium].preset
A45: Symposium readiness and recommended starting service level
A46: Recommendations only. The client confirmed the events and their readiness; the tier mapping is our suggestion and changeable on the Calculator.
A47: Symposium | B47: Recommended tier | C47: Readiness (confirmed) | H47: Config key
A48: London | B48: Lean | C48: Content is already written | H48: symposiums[london].recommendedTier / .readiness
...

Sheet Calculator
A1: Per-Deck Pricing Calculator
A2: Tiers are service levels, not locations: any symposium can run at any tier. The blue tier name per city defaults to OUR recommended starting point (based on readiness) and is fully changeable. Custom column is free-form. Headline prices round UP to the nearest \$100; the breakdown shows exact math. Estimate, not a quote.
B4: London | C4: Ottawa | D4: Canberra | E4: Custom
A5: Tier | B5: Lean | C5: Signature | D5: Premium | E5: Custom
A6: Slides per deck | B6: =INDEX(Assumptions!$B$41:$B$43,MATCH(B$5,Assumptions!$A$41:$A$43,0)) -> 20 | C6: =INDEX(Assumptions!$B$41:$B$43,MATCH(C$5,Assumptions!$A$41:$A$43,0)) -> 35 | D6: =INDEX(Assumptions!$B$41:$B$43,MATCH(D$5,Assumptions!$A$41:$A$43,0)) -> 50 | E6: 35
A7: Writing depth (1-3) | B7: =INDEX(Assumptions!$C$41:$C$43,MATCH(B$5,Assumptions!$A$41:$A$43,0)) -> 1 | C7: =INDEX(Assumptions!$C$41:$C$43,MATCH(C$5,Assumptions!$A$41:$A$43,0)) -> 2 | D7: =INDEX(Assumptions!$C$41:$C$43,MATCH(D$5,Assumptions!$A$41:$A$43,0)) -> 3 | E7: 2
A8: Depth level | B8: =CHOOSE(B7,"Deck mods only","Scripting","Full narrative") -> Deck mods only | C8: =CHOOSE(C7,"Deck mods only","Scripting","Full narrative") -> Scripting | D8: =CHOOSE(D7,"Deck mods only","Scripting","Full narrative") -> Full narrative | E8: =CHOOSE(E7,"Deck mods only","Scripting","Full narrative") -> Scripting
A9: Speakers per keynote | B9: =INDEX(Assumptions!$D$41:$D$43,MATCH(B$5,Assumptions!$A$41:$A$43,0)) -> 3 | C9: =INDEX(Assumptions!$D$41:$D$43,MATCH(C$5,Assumptions!$A$41:$A$43,0)) -> 4 | D9: =INDEX(Assumptions!$D$41:$D$43,MATCH(D$5,Assumptions!$A$41:$A$43,0)) -> 5 | E9: 4
A10: Rounds of edits | B10: =INDEX(Assumptions!$E$41:$E$43,MATCH(B$5,Assumptions!$A$41:$A$43,0)) -> 2 | C10: =INDEX(Assumptions!$E$41:$E$43,MATCH(C$5,Assumptions!$A$41:$A$43,0)) -> 3 | D10: =INDEX(Assumptions!$E$41:$E$43,MATCH(D$5,Assumptions!$A$41:$A$43,0)) -> 4 | E10: 3
A11: Dry runs managed | B11: =INDEX(Assumptions!$F$41:$F$43,MATCH(B$5,Assumptions!$A$41:$A$43,0)) -> 1 | C11: =INDEX(Assumptions!$F$41:$F$43,MATCH(C$5,Assumptions!$A$41:$A$43,0)) -> 2 | D11: =INDEX(Assumptions!$F$41:$F$43,MATCH(D$5,Assumptions!$A$41:$A$43,0)) -> 3 | E11: 2
A12: On-site days (0 = off) | B12: =INDEX(Assumptions!$G$41:$G$43,MATCH(B$5,Assumptions!$A$41:$A$43,0)) -> 0 | C12: =INDEX(Assumptions!$G$41:$G$43,MATCH(C$5,Assumptions!$A$41:$A$43,0)) -> 1 | D12: =INDEX(Assumptions!$G$41:$G$43,MATCH(D$5,Assumptions!$A$41:$A$43,0)) -> 2 | E12: 1
A14: Hours by role
A15: Content Strategy / Writing | B15: =INDEX(Assumptions!$B$19:$D$19,B7)+Assumptions!$B$33*B10+Assumptions!$B$35*B11 -> 11 | C15: =INDEX(Assumptions!$B$19:$D$19,C7)+Assumptions!$B$33*C10+Assumptions!$B$35*C11 -> 32 | D15: =INDEX(Assumptions!$B$19:$D$19,D7)+Assumptions!$B$33*D10+Assumptions!$B$35*D11 -> 65 | E15: =INDEX(Assumptions!$B$19:$D$19,E7)+Assumptions!$B$33*E10+Assumptions!$B$35*E11 -> 32
A16: Speaker Management | B16: =INDEX(Assumptions!$B$20:$D$20,B7)+Assumptions!$B$31*B9 -> 9 | C16: =INDEX(Assumptions!$B$20:$D$20,C7)+Assumptions!$B$31*C9 -> 20 | D16: =INDEX(Assumptions!$B$20:$D$20,D7)+Assumptions!$B$31*D9 -> 37 | E16: =INDEX(Assumptions!$B$20:$D$20,E7)+Assumptions!$B$31*E9 -> 20
A17: Design | B17: =INDEX(Assumptions!$B$21:$D$21,B7)+Assumptions!$B$30*MAX(0,B6-Assumptions!$B$29)+Assumptions!$B$32*B10 -> 28 | C17: =INDEX(Assumptions!$B$21:$D$21,C7)+Assumptions!$B$30*MAX(0,C6-Assumptions!$B$29)+Assumptions!$B$32*C10 -> 41 | D17: =INDEX(Assumptions!$B$21:$D$21,D7)+Assumptions!$B$30*MAX(0,D6-Assumptions!$B$29)+Assumptions!$B$32*D10 -> 54 | E17: =INDEX(Assumptions!$B$21:$D$21,E7)+Assumptions!$B$30*MAX(0,E6-Assumptions!$B$29)+Assumptions!$B$32*E10 -> 41
A18: Design Direction | B18: =INDEX(Assumptions!$B$22:$D$22,B7) -> 3 | C18: =INDEX(Assumptions!$B$22:$D$22,C7) -> 3 | D18: =INDEX(Assumptions!$B$22:$D$22,D7) -> 8 | E18: =INDEX(Assumptions!$B$22:$D$22,E7) -> 3
A19: Project Management | B19: =INDEX(Assumptions!$B$23:$D$23,B7)+Assumptions!$B$34*B11 -> 10 | C19: =INDEX(Assumptions!$B$23:$D$23,C7)+Assumptions!$B$34*C11 -> 14 | D19: =INDEX(Assumptions!$B$23:$D$23,D7)+Assumptions!$B$34*D11 -> 18 | E19: =INDEX(Assumptions!$B$23:$D$23,E7)+Assumptions!$B$34*E11 -> 14
A20: Quality Control | B20: =INDEX(Assumptions!$B$24:$D$24,B7) -> 5 | C20: =INDEX(Assumptions!$B$24:$D$24,C7) -> 5 | D20: =INDEX(Assumptions!$B$24:$D$24,D7) -> 5 | E20: =INDEX(Assumptions!$B$24:$D$24,E7) -> 5
A21: Total role hours | B21: =SUM(B15:B20) -> 66 | C21: =SUM(C15:C20) -> 115 | D21: =SUM(D15:D20) -> 187 | E21: =SUM(E15:E20) -> 115
A23: Cost by role
A24: Content Strategy / Writing | B24: =B15*Assumptions!$B$6 -> 2035 | C24: =C15*Assumptions!$B$6 -> 5920 | D24: =D15*Assumptions!$B$6 -> 12025 | E24: =E15*Assumptions!$B$6 -> 5920
A25: Speaker Management | B25: =B16*Assumptions!$B$7 -> 1665 | C25: =C16*Assumptions!$B$7 -> 3700 | D25: =D16*Assumptions!$B$7 -> 6845 | E25: =E16*Assumptions!$B$7 -> 3700
A26: Design | B26: =B17*Assumptions!$B$8 -> 4900 | C26: =C17*Assumptions!$B$8 -> 7175 | D26: =D17*Assumptions!$B$8 -> 9450 | E26: =E17*Assumptions!$B$8 -> 7175
A27: Design Direction | B27: =B18*Assumptions!$B$9 -> 600 | C27: =C18*Assumptions!$B$9 -> 600 | D27: =D18*Assumptions!$B$9 -> 1600 | E27: =E18*Assumptions!$B$9 -> 600
A28: Project Management | B28: =B19*Assumptions!$B$10 -> 1750 | C28: =C19*Assumptions!$B$10 -> 2450 | D28: =D19*Assumptions!$B$10 -> 3150 | E28: =E19*Assumptions!$B$10 -> 2450
A29: Quality Control | B29: =B20*Assumptions!$B$11 -> 500 | C29: =C20*Assumptions!$B$11 -> 500 | D29: =D20*Assumptions!$B$11 -> 500 | E29: =E20*Assumptions!$B$11 -> 500
A30: Role subtotal | B30: =SUM(B24:B29) -> 11450 | C30: =SUM(C24:C29) -> 20345 | D30: =SUM(D24:D29) -> 33570 | E30: =SUM(E24:E29) -> 20345
A31: On-site support (flat) | B31: =B12*Assumptions!$B$12 -> 0 | C31: =C12*Assumptions!$B$12 -> 3500 | D31: =D12*Assumptions!$B$12 -> 7000 | E31: =E12*Assumptions!$B$12 -> 3500
A32: Per-deck total (exact) | B32: =B30+B31 -> 11450 | C32: =C30+C31 -> 23845 | D32: =D30+D31 -> 40570 | E32: =E30+E31 -> 23845
A33: Per-deck total (rounded up) | B33: =CEILING(B32,Assumptions!$B$13) -> 11500 | C33: =CEILING(C32,Assumptions!$B$13) -> 23900 | D33: =CEILING(D32,Assumptions!$B$13) -> 40600 | E33: =CEILING(E32,Assumptions!$B$13) -> 23900
A35: Program total (London + Ottawa + Canberra, rounded) | B35: =SUM(B33:D33) -> 76000
A36: Custom column is a scratch scenario; it is not included in the program total.
